<?xml version="1.0"?>
<robot  name="Robot" >
 <link  name="G" >
  <visual >
   <origin  xyz="0.0 0.0 0.0"  rpy="0.0 0.0 0.0" />
   <geometry >
    <box  size="0.067 0.067 0.067" />
   </geometry>
   <material  name="G_Material" >
    <color  rgba="0.1568627450980392 0.42745098039215684 0.8 1.0" />
   </material>
  </visual>
  <collision  name="G_Collision" >
   <origin  xyz="0.0 0.0 0.0"  rpy="0.0 0.0 0.0" />
   <geometry >
    <box  size="0.067 0.067 0.067" />
   </geometry>
  </collision>
  <inertial >
   <origin  xyz="0.0 0.0 0.0"  rpy="0.0 0.0 0.0" />
   <mass  value="0.04903493747122909" />
   <inertia  iyy="3.66863057180579e-05"  iyz="0.0"  ixx="3.66863057180579e-05"  izz="3.66863057180579e-05"  ixz="0.0"  ixy="0.0" />
  </inertial>
 </link>
 <link  name="L6" >
  <visual >
   <origin  xyz="-1.0758476626537717e-18 0.0 0.09617692030835673"  rpy="0.0 0.0 0.0" />
   <geometry >
    <box  size="0.03350000083446503 0.03350000083446503 0.15885383978224843" />
   </geometry>
   <material  name="L6_Material" >
    <color  rgba="0.37254901960784315 0.5019607843137255 0.8352941176470589 1.0" />
   </material>
  </visual>
  <collision  name="L6_0_Collision" >
   <origin  xyz="-1.0758476626537717e-18 0.0 0.09617692030835673"  rpy="0.0 0.0 0.0" />
   <geometry >
    <box  size="0.03350000083446503 0.03350000083446503 0.15885383978224843" />
   </geometry>
  </collision>
  <collision  name="L6_0_Collision" >
   <origin  xyz="-1.0758476626537717e-18 0.0 0.09617692030835673"  rpy="0.0 0.0 0.0" />
   <geometry >
    <box  size="0.03350000083446503 0.03350000083446503 0.15885383978224843" />
   </geometry>
  </collision>
  <visual >
   <origin  xyz="0.012887707321319802 0.0 0.11627789665280329"  rpy="3.141592653589793 0.16781260553930433 3.141592653589793" />
   <geometry >
    <box  size="0.03350000083446503 0.03350000083446503 0.12081969654730149" />
   </geometry>
   <material  name="L6_Material" >
    <color  rgba="0.37254901960784315 0.5019607843137255 0.8352941176470589 1.0" />
   </material>
  </visual>
  <collision  name="L6_1_Collision" >
   <origin  xyz="0.012887707321319802 0.0 0.11627789665280329"  rpy="3.141592653589793 0.16781260553930433 3.141592653589793" />
   <geometry >
    <box  size="0.03350000083446503 0.03350000083446503 0.12081969654730149" />
   </geometry>
  </collision>
  <collision  name="L6_1_Collision" >
   <origin  xyz="0.012887707321319802 0.0 0.11627789665280329"  rpy="3.141592653589793 0.16781260553930433 3.141592653589793" />
   <geometry >
    <box  size="0.03350000083446503 0.03350000083446503 0.12081969654730149" />
   </geometry>
  </collision>
  <visual >
   <origin  xyz="0.012887707321319804 0.0 0.020100976344446558"  rpy="0.0 0.570127412660451 0.0" />
   <geometry >
    <box  size="0.03350000083446503 0.03350000083446503 0.014255302535946104" />
   </geometry>
   <material  name="L6_Material" >
    <color  rgba="0.37254901960784315 0.5019607843137255 0.8352941176470589 1.0" />
   </material>
  </visual>
  <collision  name="L6_2_Collision" >
   <origin  xyz="0.012887707321319804 0.0 0.020100976344446558"  rpy="0.0 0.570127412660451 0.0" />
   <geometry >
    <box  size="0.03350000083446503 0.03350000083446503 0.014255302535946104" />
   </geometry>
  </collision>
  <collision  name="L6_2_Collision" >
   <origin  xyz="0.012887707321319804 0.0 0.020100976344446558"  rpy="0.0 0.570127412660451 0.0" />
   <geometry >
    <box  size="0.03350000083446503 0.03350000083446503 0.014255302535946104" />
   </geometry>
  </collision>
  <inertial >
   <origin  xyz="0.00859 0.0 0.07752"  rpy="0.0 0.0 0.0" />
   <mass  value="0.2202180625918948" />
   <inertia  iyy="0.00686924818725791"  iyz="2.682219500035425e-21"  ixx="0.006822085358422034"  izz="8.8352784345203e-05"  ixz="5.7156135772371623e-05"  ixy="1.7154560739944766e-21" />
  </inertial>
 </link>
 <link  name="L5" >
  <visual >
   <origin  xyz="-7.632783294297951e-17 0.0 0.10606601717798211"  rpy="0.0 0.0 0.0" />
   <geometry >
    <box  size="0.03350000083446503 0.03350000083446503 0.17863203352149926" />
   </geometry>
   <material  name="L5_Material" >
    <color  rgba="0.5176470588235295 0.5843137254901961 0.8705882352941177 1.0" />
   </material>
  </visual>
  <collision  name="L5_0_Collision" >
   <origin  xyz="-7.632783294297951e-17 0.0 0.10606601717798211"  rpy="0.0 0.0 0.0" />
   <geometry >
    <box  size="0.03350000083446503 0.03350000083446503 0.17863203352149926" />
   </geometry>
  </collision>
  <collision  name="L5_0_Collision" >
   <origin  xyz="-7.632783294297951e-17 0.0 0.10606601717798211"  rpy="0.0 0.0 0.0" />
   <geometry >
    <box  size="0.03350000083446503 0.03350000083446503 0.17863203352149926" />
   </geometry>
  </collision>
  <visual >
   <origin  xyz="-0.009439875528840458 0.0 0.06013943173991587"  rpy="0.0 -0.15569608012829228 0.0" />
   <geometry >
    <box  size="0.03350000083446503 0.03350000083446503 0.0882515905309049" />
   </geometry>
   <material  name="L5_Material" >
    <color  rgba="0.5176470588235295 0.5843137254901961 0.8705882352941177 1.0" />
   </material>
  </visual>
  <collision  name="L5_1_Collision" >
   <origin  xyz="-0.009439875528840458 0.0 0.06013943173991587"  rpy="0.0 -0.15569608012829228 0.0" />
   <geometry >
    <box  size="0.03350000083446503 0.03350000083446503 0.0882515905309049" />
   </geometry>
  </collision>
  <collision  name="L5_1_Collision" >
   <origin  xyz="-0.009439875528840458 0.0 0.06013943173991587"  rpy="0.0 -0.15569608012829228 0.0" />
   <geometry >
    <box  size="0.03350000083446503 0.03350000083446503 0.0882515905309049" />
   </geometry>
  </collision>
  <visual >
   <origin  xyz="-0.009439875528840534 0.0 0.166205448917898"  rpy="-3.141592653589793 -0.20271937822947983 3.141592653589793" />
   <geometry >
    <box  size="0.03350000083446503 0.03350000083446503 0.060273396245943606" />
   </geometry>
   <material  name="L5_Material" >
    <color  rgba="0.5176470588235295 0.5843137254901961 0.8705882352941177 1.0" />
   </material>
  </visual>
  <collision  name="L5_2_Collision" >
   <origin  xyz="-0.009439875528840534 0.0 0.166205448917898"  rpy="-3.141592653589793 -0.20271937822947983 3.141592653589793" />
   <geometry >
    <box  size="0.03350000083446503 0.03350000083446503 0.060273396245943606" />
   </geometry>
  </collision>
  <collision  name="L5_2_Collision" >
   <origin  xyz="-0.009439875528840534 0.0 0.166205448917898"  rpy="-3.141592653589793 -0.20271937822947983 3.141592653589793" />
   <geometry >
    <box  size="0.03350000083446503 0.03350000083446503 0.060273396245943606" />
   </geometry>
  </collision>
  <inertial >
   <origin  xyz="-0.00629 0.0 0.1108"  rpy="0.0 0.0 0.0" />
   <mass  value="0.2221588496975448" />
   <inertia  iyy="0.03786147396654845"  iyz="5.658604733509615e-21"  ixx="0.03767992185499816"  izz="0.000223105075132593"  ixz="0.002274078441000862"  ixy="-9.596135644643112e-22" />
  </inertial>
 </link>
 <link  name="EE" >
  <visual >
   <origin  xyz="0.0 0.0 0.0"  rpy="0.0 0.0 0.0" />
   <geometry >
    <sphere  radius="0.002142857142857143" />
   </geometry>
   <material  name="EE_Material" >
    <color  rgba="0.6431372549019608 0.6666666666666666 0.9058823529411765 1.0" />
   </material>
  </visual>
  <collision  name="EE_Collision" >
   <origin  xyz="0.0 0.0 0.0"  rpy="0.0 0.0 0.0" />
   <geometry >
    <sphere  radius="0.002142857142857143" />
   </geometry>
  </collision>
  <inertial >
   <origin  xyz="0.0 0.0 0.0"  rpy="0.0 0.0 0.0" />
   <mass  value="2.982076683750377e-05" />
   <inertia  iyy="5.477283704847632e-11"  iyz="0.0"  ixx="5.477283704847632e-11"  izz="5.477283704847632e-11"  ixz="0.0"  ixy="0.0" />
  </inertial>
 </link>
 <link  name="L4" >
  <visual >
   <origin  xyz="0.0 0.0 0.10762"  rpy="0.0 0.0 0.0" />
   <geometry >
    <box  size="0.0335 0.0335 0.18173243250030885" />
   </geometry>
   <material  name="L4_Material" >
    <color  rgba="0.01568627450980392 0.5058823529411764 0.29411764705882354 1.0" />
   </material>
  </visual>
  <collision  name="L4_Collision" >
   <origin  xyz="0.0 0.0 0.10762"  rpy="0.0 0.0 0.0" />
   <geometry >
    <box  size="0.0335 0.0335 0.18173243250030885" />
   </geometry>
  </collision>
  <inertial >
   <origin  xyz="0.0 0.0 0.10762"  rpy="0.0 0.0 0.0" />
   <mass  value="0.1475613413716542" />
   <inertia  iyy="0.0004199217898199813"  iyz="0.0"  ixx="0.0004199217898199813"  izz="2.7600119225723156e-05"  ixz="0.0"  ixy="0.0" />
  </inertial>
 </link>
 <link  name="L3" >
  <visual >
   <origin  xyz="-0.009016166054061345 0.0 0.08694993530581607"  rpy="0.0 0.08880382907284035 0.0" />
   <geometry >
    <box  size="0.03350000083446503 0.03350000083446503 0.1698251820622928" />
   </geometry>
   <material  name="L3_Material" >
    <color  rgba="0.0 0.6627450980392157 0.3607843137254902 1.0" />
   </material>
  </visual>
  <collision  name="L3_0_Collision" >
   <origin  xyz="-0.009016166054061345 0.0 0.08694993530581607"  rpy="0.0 0.08880382907284035 0.0" />
   <geometry >
    <box  size="0.03350000083446503 0.03350000083446503 0.1698251820622928" />
   </geometry>
  </collision>
  <collision  name="L3_0_Collision" >
   <origin  xyz="-0.009016166054061345 0.0 0.08694993530581607"  rpy="0.0 0.08880382907284035 0.0" />
   <geometry >
    <box  size="0.03350000083446503 0.03350000083446503 0.1698251820622928" />
   </geometry>
  </collision>
  <visual >
   <origin  xyz="-0.009016166054061331 0.0 -0.007156028904748216"  rpy="0.0 0.8999156177730998 0.0" />
   <geometry >
    <box  size="0.03350000083446503 0.03350000083446503 0.02302172886644268" />
   </geometry>
   <material  name="L3_Material" >
    <color  rgba="0.0 0.6627450980392157 0.3607843137254902 1.0" />
   </material>
  </visual>
  <collision  name="L3_1_Collision" >
   <origin  xyz="-0.009016166054061331 0.0 -0.007156028904748216"  rpy="0.0 0.8999156177730998 0.0" />
   <geometry >
    <box  size="0.03350000083446503 0.03350000083446503 0.02302172886644268" />
   </geometry>
  </collision>
  <collision  name="L3_1_Collision" >
   <origin  xyz="-0.009016166054061331 0.0 -0.007156028904748216"  rpy="0.0 0.8999156177730998 0.0" />
   <geometry >
    <box  size="0.03350000083446503 0.03350000083446503 0.02302172886644268" />
   </geometry>
  </collision>
  <visual >
   <origin  xyz="-1.3877787807814457e-17 0.0 0.0941059642105643"  rpy="0.0 0.0 0.0" />
   <geometry >
    <box  size="0.03350000083446503 0.03350000083446503 0.15471192758666352" />
   </geometry>
   <material  name="L3_Material" >
    <color  rgba="0.0 0.6627450980392157 0.3607843137254902 1.0" />
   </material>
  </visual>
  <collision  name="L3_2_Collision" >
   <origin  xyz="-1.3877787807814457e-17 0.0 0.0941059642105643"  rpy="0.0 0.0 0.0" />
   <geometry >
    <box  size="0.03350000083446503 0.03350000083446503 0.15471192758666352" />
   </geometry>
  </collision>
  <collision  name="L3_2_Collision" >
   <origin  xyz="-1.3877787807814457e-17 0.0 0.0941059642105643"  rpy="0.0 0.0 0.0" />
   <geometry >
    <box  size="0.03350000083446503 0.03350000083446503 0.15471192758666352" />
   </geometry>
  </collision>
  <inertial >
   <origin  xyz="-0.00601 0.0 0.05797"  rpy="0.0 0.0 0.0" />
   <mass  value="0.20943533725023145" />
   <inertia  iyy="0.0017849828520290257"  iyz="-1.7855502526654325e-21"  ixx="0.0015548458244146585"  izz="0.0002693101641041047"  ixz="-0.0004982832080656236"  ixy="4.53313991568725e-21" />
  </inertial>
 </link>
 <link  name="L8" >
  <visual >
   <origin  xyz="0.0 0.0 0.0744"  rpy="0.0 0.0 0.0" />
   <geometry >
    <box  size="0.0335 0.0335 0.11529532586744787" />
   </geometry>
   <material  name="L8_Material" >
    <color  rgba="0.0 0.8274509803921568 0.4196078431372549 1.0" />
   </material>
  </visual>
  <collision  name="L8_Collision" >
   <origin  xyz="0.0 0.0 0.0744"  rpy="0.0 0.0 0.0" />
   <geometry >
    <box  size="0.0335 0.0335 0.11529532586744787" />
   </geometry>
  </collision>
  <inertial >
   <origin  xyz="0.0 0.0 0.0744"  rpy="0.0 0.0 0.0" />
   <mass  value="0.09361638263909594" />
   <inertia  iyy="0.00011245872490480118"  iyz="0.0"  ixx="0.00011245872490480118"  izz="1.7510164236120905e-05"  ixz="0.0"  ixy="0.0" />
  </inertial>
 </link>
 <link  name="L7" >
  <visual >
   <origin  xyz="0.0 0.0 0.034"  rpy="0.0 0.0 0.0" />
   <geometry >
    <box  size="0.0335 0.0335 0.0345" />
   </geometry>
   <material  name="L7_Material" >
    <color  rgba="0.0 1.0 0.4666666666666667 1.0" />
   </material>
  </visual>
  <collision  name="L7_Collision" >
   <origin  xyz="0.0 0.0 0.034"  rpy="0.0 0.0 0.0" />
   <geometry >
    <box  size="0.0335 0.0335 0.0345" />
   </geometry>
  </collision>
  <inertial >
   <origin  xyz="0.0 0.0 0.034"  rpy="0.0 0.0 0.0" />
   <mass  value="0.02801297604000001" />
   <inertia  iyy="5.398333924375002e-06"  iyz="0.0"  ixx="5.398333924375002e-06"  izz="5.2395937268150025e-06"  ixz="0.0"  ixy="0.0" />
  </inertial>
 </link>
 <joint  type="revolute"  name="Main_ground" >
  <parent  link="G" />
  <child  link="L6" />
  <origin  xyz="0.0 0.0 0.0"  rpy="3.141592653589793 0.15660187698201544 3.141592653589793" />
  <axis  xyz="0 1 0" />
  <limit  lower="-3.141592653589793"  upper="3.141592653589793"  effort="10.2"  velocity="23.99988291783386" />
  <dynamics  damping="0.05"  friction="0" />
 </joint>
 <joint  type="fixed"  name="Main_ground_G_WeldActuator" >
  <parent  link="G" />
  <child  link="Main_ground_GActuator" />
  <origin  xyz="0.0 0.03675000041723252 0.0"  rpy="-1.5707963267948966 0.15660187698201522 -3.141592653589793" />
 </joint>
 <link  name="Main_ground_GActuator" >
  <visual >
   <geometry >
    <cylinder  radius="0.048"  length="0.04" />
   </geometry>
   <material  name="Main_ground_GActuator_Material" >
    <color  rgba="0.1568627450980392 0.42745098039215684 0.8 0.9" />
   </material>
  </visual>
  <inertial >
   <inertia  iyy="0.0067466666666666664"  iyz="0.0"  ixx="0.0067466666666666664"  izz="0.01056"  ixz="0.0"  ixy="0.0" />
   <mass  value="0.44" />
  </inertial>
 </link>
 <link  name="Main_ground_GUnit" >
  <visual >
   <geometry >
    <cylinder  radius="0.016750000417232513"  length="0.03350000083446503" />
   </geometry>
   <material  name="Main_ground_GUnit_Material" >
    <color  rgba="0.1568627450980392 0.42745098039215684 0.8 0.9" />
   </material>
  </visual>
  <inertial >
   <inertia  iyy="0.0006979166840513548"  iyz="0.0"  ixx="0.0006979166840513548"  izz="0.0008375000208616257"  ixz="0.0"  ixy="0.0" />
   <mass  value="0.1" />
  </inertial>
 </link>
 <joint  type="fixed"  name="Main_ground_G_WeldUnit" >
  <parent  link="G" />
  <child  link="Main_ground_GUnit" />
  <origin  xyz="0.0 0.0 0.0"  rpy="-1.5707963267948966 0.15660187698201522 -3.141592653589793" />
 </joint>
 <joint  type="revolute"  name="Main_knee" >
  <parent  link="L6" />
  <child  link="L5" />
  <origin  xyz="-2.1516953253075435e-18 0.0 0.19235384061671346"  rpy="0.0 0.2984989315861801 0.0" />
  <axis  xyz="0 1 0" />
  <limit  lower="-3.141592653589793"  upper="3.141592653589793"  effort="600.0"  velocity="6.283185307179586" />
  <dynamics  damping="0.05"  friction="0" />
 </joint>
 <link  name="Main_knee_L6Unit" >
  <visual >
   <geometry >
    <cylinder  radius="0.016"  length="0.03" />
   </geometry>
   <material  name="Main_knee_L6Unit_Material" >
    <color  rgba="0.37254901960784315 0.5019607843137255 0.8352941176470589 0.9" />
   </material>
  </visual>
  <inertial >
   <inertia  iyy="0.00065"  iyz="0.0"  ixx="0.00065"  izz="0.0008"  ixz="0.0"  ixy="0.0" />
   <mass  value="0.1" />
  </inertial>
 </link>
 <joint  type="fixed"  name="Main_knee_L6_WeldUnit" >
  <parent  link="L6" />
  <child  link="Main_knee_L6Unit" />
  <origin  xyz="-2.1516953253075435e-18 0.0 0.19235384061671346"  rpy="1.5707963267948966 0.2984989315861799 -1.1102230246251565e-16" />
 </joint>
 <joint  type="fixed"  name="Main_ee" >
  <parent  link="L5" />
  <child  link="EE" />
  <origin  xyz="-1.5265566588595902e-16 0.0 0.21213203435596426"  rpy="3.141592653589793 0.14189705460416469 3.141592653589793" />
 </joint>
 <link  name="Main_ee_L5Unit" >
  <visual >
   <geometry >
    <cylinder  radius="0.016"  length="0.03" />
   </geometry>
   <material  name="Main_ee_L5Unit_Material" >
    <color  rgba="0.5176470588235295 0.5843137254901961 0.8705882352941177 0.9" />
   </material>
  </visual>
  <inertial >
   <inertia  iyy="0.00065"  iyz="0.0"  ixx="0.00065"  izz="0.0008"  ixz="0.0"  ixy="0.0" />
   <mass  value="0.1" />
  </inertial>
 </link>
 <joint  type="fixed"  name="Main_ee_L5_WeldUnit" >
  <parent  link="L5" />
  <child  link="Main_ee_L5Unit" />
  <origin  xyz="-1.5265566588595902e-16 0.0 0.21213203435596426"  rpy="-1.5707963267948966 0.14189705460416469 -3.141592653589793" />
 </joint>
 <link  name="Main_connection_2_L5Pseudo" >
  <visual >
   <geometry >
    <sphere  radius="0.02392857202461788" />
   </geometry>
   <material  name="Main_connection_2_L5Pseudo_Material" >
    <color  rgba="0.5176470588235295 0.5843137254901961 0.8705882352941177 0.5" />
   </material>
  </visual>
  <inertial >
   <mass  value="0.05" />
   <inertia  iyy="1.145153118274651e-05"  iyz="0.0"  ixx="1.145153118274651e-05"  izz="1.145153118274651e-05"  ixz="0.0"  ixy="0.0" />
  </inertial>
 </link>
 <joint  type="revolute"  name="Main_connection_2_L5_revolute" >
  <parent  link="L5" />
  <child  link="Main_connection_2_L5Pseudo" />
  <origin  xyz="-0.018879751057680916 0.0 0.12027886347983177"  rpy="3.141592653589793 0.14189705460416469 3.141592653589793" />
  <axis  xyz="0 1 0" />
  <limit  lower="-3.141592653589793"  upper="3.141592653589793"  effort="600.0"  velocity="6.283185307179586" />
  <dynamics  damping="0.05"  friction="0" />
 </joint>
 <joint  type="fixed"  name="Main_connection_2_L5_Weld" >
  <parent  link="L4" />
  <child  link="Main_connection_2_L4Pseudo" />
  <origin  xyz="-6.938893903907228e-18 0.0 0.21523243250030882"  rpy="3.141592653589793 -0.39085976039688086 3.141592653589793" />
 </joint>
 <link  name="Main_connection_2_L4Pseudo" >
  <visual >
   <geometry >
    <sphere  radius="0.02392857142857143" />
   </geometry>
   <material  name="Main_connection_2_L4Pseudo_Material" >
    <color  rgba="0.01568627450980392 0.5058823529411764 0.29411764705882354 0.5" />
   </material>
  </visual>
  <inertial >
   <mass  value="0.05" />
   <inertia  iyy="1.1451530612244902e-05"  iyz="0.0"  ixx="1.1451530612244902e-05"  izz="1.1451530612244902e-05"  ixz="0.0"  ixy="0.0" />
  </inertial>
 </link>
 <joint  type="revolute"  name="branch_0" >
  <parent  link="L3" />
  <child  link="L4" />
  <origin  xyz="-2.7755575615628914e-17 0.0 0.18821192842112858"  rpy="0.0 -0.46169025601692426 0.0" />
  <axis  xyz="0 1 0" />
  <limit  lower="-3.141592653589793"  upper="3.141592653589793"  effort="600.0"  velocity="6.283185307179586" />
  <dynamics  damping="0.05"  friction="0" />
 </joint>
 <link  name="branch_0_L3Unit" >
  <visual >
   <geometry >
    <cylinder  radius="0.016"  length="0.03" />
   </geometry>
   <material  name="branch_0_L3Unit_Material" >
    <color  rgba="0.0 0.6627450980392157 0.3607843137254902 0.9" />
   </material>
  </visual>
  <inertial >
   <inertia  iyy="0.00065"  iyz="0.0"  ixx="0.00065"  izz="0.0008"  ixz="0.0"  ixy="0.0" />
   <mass  value="0.1" />
  </inertial>
 </link>
 <joint  type="fixed"  name="branch_0_L3_WeldUnit" >
  <parent  link="L3" />
  <child  link="branch_0_L3Unit" />
  <origin  xyz="-2.7755575615628914e-17 0.0 0.18821192842112858"  rpy="1.5707963267948966 -0.46169025601692426 1.1102230246251565e-16" />
 </joint>
 <joint  type="revolute"  name="Ground_connection" >
  <parent  link="G" />
  <child  link="L3" />
  <origin  xyz="-0.037 0.0 0.075"  rpy="3.141592653589793 -0.07083049562004318 3.141592653589793" />
  <axis  xyz="0 1 0" />
  <limit  lower="-3.141592653589793"  upper="3.141592653589793"  effort="10.2"  velocity="23.99988291783386" />
  <dynamics  damping="0.05"  friction="0" />
 </joint>
 <joint  type="fixed"  name="Ground_connection_G_WeldActuator" >
  <parent  link="G" />
  <child  link="Ground_connection_GActuator" />
  <origin  xyz="-0.037 0.03675000041723252 0.075"  rpy="-1.5707963267948966 -0.07083049562004318 -3.141592653589793" />
 </joint>
 <link  name="Ground_connection_GActuator" >
  <visual >
   <geometry >
    <cylinder  radius="0.048"  length="0.04" />
   </geometry>
   <material  name="Ground_connection_GActuator_Material" >
    <color  rgba="0.1568627450980392 0.42745098039215684 0.8 0.9" />
   </material>
  </visual>
  <inertial >
   <inertia  iyy="0.0067466666666666664"  iyz="0.0"  ixx="0.0067466666666666664"  izz="0.01056"  ixz="0.0"  ixy="0.0" />
   <mass  value="0.44" />
  </inertial>
 </link>
 <link  name="Ground_connection_GUnit" >
  <visual >
   <geometry >
    <cylinder  radius="0.016750000417232513"  length="0.03350000083446503" />
   </geometry>
   <material  name="Ground_connection_GUnit_Material" >
    <color  rgba="0.1568627450980392 0.42745098039215684 0.8 0.9" />
   </material>
  </visual>
  <inertial >
   <inertia  iyy="0.0006979166840513548"  iyz="0.0"  ixx="0.0006979166840513548"  izz="0.0008375000208616257"  ixz="0.0"  ixy="0.0" />
   <mass  value="0.1" />
  </inertial>
 </link>
 <joint  type="fixed"  name="Ground_connection_G_WeldUnit" >
  <parent  link="G" />
  <child  link="Ground_connection_GUnit" />
  <origin  xyz="-0.037 0.0 0.075"  rpy="-1.5707963267948966 -0.07083049562004318 -3.141592653589793" />
 </joint>
 <joint  type="revolute"  name="branch_1" >
  <parent  link="L3" />
  <child  link="L8" />
  <origin  xyz="-0.018032332108122662 0.0 -0.014312057809496445"  rpy="0.0 0.4128054324703412 0.0" />
  <axis  xyz="0 1 0" />
  <limit  lower="-3.141592653589793"  upper="3.141592653589793"  effort="600.0"  velocity="6.283185307179586" />
  <dynamics  damping="0.05"  friction="0" />
 </joint>
 <link  name="branch_1_L3Unit" >
  <visual >
   <geometry >
    <cylinder  radius="0.016"  length="0.03" />
   </geometry>
   <material  name="branch_1_L3Unit_Material" >
    <color  rgba="0.0 0.6627450980392157 0.3607843137254902 0.9" />
   </material>
  </visual>
  <inertial >
   <inertia  iyy="0.00065"  iyz="0.0"  ixx="0.00065"  izz="0.0008"  ixz="0.0"  ixy="0.0" />
   <mass  value="0.1" />
  </inertial>
 </link>
 <joint  type="fixed"  name="branch_1_L3_WeldUnit" >
  <parent  link="L3" />
  <child  link="branch_1_L3Unit" />
  <origin  xyz="-0.018032332108122662 0.0 -0.014312057809496445"  rpy="1.5707963267948961 0.4128054324703412 -1.1102230246251565e-16" />
 </joint>
 <link  name="Main_connection_1_L7Pseudo" >
  <visual >
   <geometry >
    <sphere  radius="0.02392857142857143" />
   </geometry>
   <material  name="Main_connection_1_L7Pseudo_Material" >
    <color  rgba="0.0 1.0 0.4666666666666667 0.5" />
   </material>
  </visual>
  <inertial >
   <mass  value="0.05" />
   <inertia  iyy="1.1451530612244902e-05"  iyz="0.0"  ixx="1.1451530612244902e-05"  izz="1.1451530612244902e-05"  ixz="0.0"  ixy="0.0" />
  </inertial>
 </link>
 <joint  type="revolute"  name="Main_connection_1_L7_revolute" >
  <parent  link="L7" />
  <child  link="Main_connection_1_L7Pseudo" />
  <origin  xyz="1.3877787807814457e-17 0.0 0.06800000000000002"  rpy="0.0 0.0 0.0" />
  <axis  xyz="0 1 0" />
  <limit  lower="-3.141592653589793"  upper="3.141592653589793"  effort="600.0"  velocity="6.283185307179586" />
  <dynamics  damping="0.05"  friction="0" />
 </joint>
 <joint  type="fixed"  name="Main_connection_1_L7_Weld" >
  <parent  link="L6" />
  <child  link="Main_connection_1_L6Pseudo" />
  <origin  xyz="0.025775414642639605 0.0 0.04020195268889311"  rpy="0.0 -1.4141944498128816 0.0" />
 </joint>
 <link  name="Main_connection_1_L6Pseudo" >
  <visual >
   <geometry >
    <sphere  radius="0.02392857202461788" />
   </geometry>
   <material  name="Main_connection_1_L6Pseudo_Material" >
    <color  rgba="0.37254901960784315 0.5019607843137255 0.8352941176470589 0.5" />
   </material>
  </visual>
  <inertial >
   <mass  value="0.05" />
   <inertia  iyy="1.145153118274651e-05"  iyz="0.0"  ixx="1.145153118274651e-05"  izz="1.145153118274651e-05"  ixz="0.0"  ixy="0.0" />
  </inertial>
 </link>
 <joint  type="revolute"  name="branch_2" >
  <parent  link="L8" />
  <child  link="L7" />
  <origin  xyz="-6.938893903907228e-18 0.0 0.14879532586744787"  rpy="3.141592653589793 -1.0871603987045118 3.141592653589793" />
  <axis  xyz="0 1 0" />
  <limit  lower="-3.141592653589793"  upper="3.141592653589793"  effort="600.0"  velocity="6.283185307179586" />
  <dynamics  damping="0.05"  friction="0" />
 </joint>
 <link  name="branch_2_L8Unit" >
  <visual >
   <geometry >
    <cylinder  radius="0.016"  length="0.03" />
   </geometry>
   <material  name="branch_2_L8Unit_Material" >
    <color  rgba="0.0 0.8274509803921568 0.4196078431372549 0.9" />
   </material>
  </visual>
  <inertial >
   <inertia  iyy="0.00065"  iyz="0.0"  ixx="0.00065"  izz="0.0008"  ixz="0.0"  ixy="0.0" />
   <mass  value="0.1" />
  </inertial>
 </link>
 <joint  type="fixed"  name="branch_2_L8_WeldUnit" >
  <parent  link="L8" />
  <child  link="branch_2_L8Unit" />
  <origin  xyz="-6.938893903907228e-18 0.0 0.14879532586744787"  rpy="-1.5707963267948968 -1.0871603987045122 -3.141592653589793" />
 </joint>
</robot>
