<?xml version="1.0"?>
<robot  name="Robot" >
 <link  name="G" >
  <visual >
   <origin  xyz="0.0 0.0 0.0"  rpy="0.0 0.0 0.0" />
   <geometry >
    <box  size="0.067 0.067 0.067" />
   </geometry>
   <material  name="G_Material" >
    <color  rgba="0.1568627450980392 0.42745098039215684 0.8 1.0" />
   </material>
  </visual>
  <collision  name="G_Collision" >
   <origin  xyz="0.0 0.0 0.0"  rpy="0.0 0.0 0.0" />
   <geometry >
    <box  size="0.067 0.067 0.067" />
   </geometry>
  </collision>
  <inertial >
   <origin  xyz="0.0 0.0 0.0"  rpy="0.0 0.0 0.0" />
   <mass  value="0.04903493747122909" />
   <inertia  iyy="3.66863057180579e-05"  iyz="0.0"  ixx="3.66863057180579e-05"  izz="3.66863057180579e-05"  ixz="0.0"  ixy="0.0" />
  </inertial>
 </link>
 <link  name="L6" >
  <visual >
   <origin  xyz="0.0 0.0 0.08582"  rpy="0.0 0.0 0.0" />
   <geometry >
    <box  size="0.0335 0.0335 0.1381420694352058" />
   </geometry>
   <material  name="L6_Material" >
    <color  rgba="0.37254901960784315 0.5019607843137255 0.8352941176470589 1.0" />
   </material>
  </visual>
  <collision  name="L6_Collision" >
   <origin  xyz="0.0 0.0 0.08582"  rpy="0.0 0.0 0.0" />
   <geometry >
    <box  size="0.0335 0.0335 0.1381420694352058" />
   </geometry>
  </collision>
  <inertial >
   <origin  xyz="0.0 0.0 0.08582"  rpy="0.0 0.0 0.0" />
   <mass  value="0.11216726032476629" />
   <inertia  iyy="0.00018886612386087633"  iyz="0.0"  ixx="0.00018886612386087633"  izz="2.0979951316578163e-05"  ixz="0.0"  ixy="0.0" />
  </inertial>
 </link>
 <link  name="L5" >
  <visual >
   <origin  xyz="0.0 0.0 0.11646995320682499"  rpy="0.0 0.0 0.0" />
   <geometry >
    <box  size="0.03350000083446503 0.03350000083446503 0.19943990557918495" />
   </geometry>
   <material  name="L5_Material" >
    <color  rgba="0.5176470588235295 0.5843137254901961 0.8705882352941177 1.0" />
   </material>
  </visual>
  <collision  name="L5_0_Collision" >
   <origin  xyz="0.0 0.0 0.11646995320682499"  rpy="0.0 0.0 0.0" />
   <geometry >
    <box  size="0.03350000083446503 0.03350000083446503 0.19943990557918495" />
   </geometry>
  </collision>
  <collision  name="L5_0_Collision" >
   <origin  xyz="0.0 0.0 0.11646995320682499"  rpy="0.0 0.0 0.0" />
   <geometry >
    <box  size="0.03350000083446503 0.03350000083446503 0.19943990557918495" />
   </geometry>
  </collision>
  <visual >
   <origin  xyz="0.004425858221859348 0.0 0.0610302554803763"  rpy="0.0 0.0723923572264833 0.0" />
   <geometry >
    <box  size="0.03350000083446503 0.03350000083446503 0.08888104843379385" />
   </geometry>
   <material  name="L5_Material" >
    <color  rgba="0.5176470588235295 0.5843137254901961 0.8705882352941177 1.0" />
   </material>
  </visual>
  <collision  name="L5_1_Collision" >
   <origin  xyz="0.004425858221859348 0.0 0.0610302554803763"  rpy="0.0 0.0723923572264833 0.0" />
   <geometry >
    <box  size="0.03350000083446503 0.03350000083446503 0.08888104843379385" />
   </geometry>
  </collision>
  <collision  name="L5_1_Collision" >
   <origin  xyz="0.004425858221859348 0.0 0.0610302554803763"  rpy="0.0 0.0723923572264833 0.0" />
   <geometry >
    <box  size="0.03350000083446503 0.03350000083446503 0.08888104843379385" />
   </geometry>
  </collision>
  <visual >
   <origin  xyz="0.004425858221859348 0.0 0.1775002086872013"  rpy="3.141592653589793 0.07966298504578817 3.141592653589793" />
   <geometry >
    <box  size="0.03350000083446503 0.03350000083446503 0.07773215827431071" />
   </geometry>
   <material  name="L5_Material" >
    <color  rgba="0.5176470588235295 0.5843137254901961 0.8705882352941177 1.0" />
   </material>
  </visual>
  <collision  name="L5_2_Collision" >
   <origin  xyz="0.004425858221859348 0.0 0.1775002086872013"  rpy="3.141592653589793 0.07966298504578817 3.141592653589793" />
   <geometry >
    <box  size="0.03350000083446503 0.03350000083446503 0.07773215827431071" />
   </geometry>
  </collision>
  <collision  name="L5_2_Collision" >
   <origin  xyz="0.004425858221859348 0.0 0.1775002086872013"  rpy="3.141592653589793 0.07966298504578817 3.141592653589793" />
   <geometry >
    <box  size="0.03350000083446503 0.03350000083446503 0.07773215827431071" />
   </geometry>
  </collision>
  <inertial >
   <origin  xyz="0.00295 0.0 0.11833"  rpy="0.0 0.0 0.0" />
   <mass  value="0.21451713129824346" />
   <inertia  iyy="0.03576453410005396"  iyz="-8.128626556038429e-21"  ixx="0.03572286889744648"  izz="8.178884637295921e-05"  ixz="0.0007258076803546198"  ixy="-1.352089894581833e-21" />
  </inertial>
 </link>
 <link  name="EE" >
  <visual >
   <origin  xyz="0.0 0.0 0.0"  rpy="0.0 0.0 0.0" />
   <geometry >
    <sphere  radius="0.002142857142857143" />
   </geometry>
   <material  name="EE_Material" >
    <color  rgba="0.6431372549019608 0.6666666666666666 0.9058823529411765 1.0" />
   </material>
  </visual>
  <collision  name="EE_Collision" >
   <origin  xyz="0.0 0.0 0.0"  rpy="0.0 0.0 0.0" />
   <geometry >
    <sphere  radius="0.002142857142857143" />
   </geometry>
  </collision>
  <inertial >
   <origin  xyz="0.0 0.0 0.0"  rpy="0.0 0.0 0.0" />
   <mass  value="2.982076683750377e-05" />
   <inertia  iyy="5.477283704847632e-11"  iyz="0.0"  ixx="5.477283704847632e-11"  izz="5.477283704847632e-11"  ixz="0.0"  ixy="0.0" />
  </inertial>
 </link>
 <link  name="L3" >
  <visual >
   <origin  xyz="0.0 0.0 0.0904"  rpy="0.0 0.0 0.0" />
   <geometry >
    <box  size="0.0335 0.0335 0.14730099557248016" />
   </geometry>
   <material  name="L3_Material" >
    <color  rgba="0.01568627450980392 0.5058823529411764 0.29411764705882354 1.0" />
   </material>
  </visual>
  <collision  name="L3_Collision" >
   <origin  xyz="0.0 0.0 0.0904"  rpy="0.0 0.0 0.0" />
   <geometry >
    <box  size="0.0335 0.0335 0.14730099557248016" />
   </geometry>
  </collision>
  <inertial >
   <origin  xyz="0.0 0.0 0.0904"  rpy="0.0 0.0 0.0" />
   <mass  value="0.11960403651130531" />
   <inertia  iyy="0.00022744534789947404"  iyz="0.0"  ixx="0.00022744534789947404"  izz="2.23709383291354e-05"  ixz="0.0"  ixy="0.0" />
  </inertial>
 </link>
 <link  name="L4" >
  <visual >
   <origin  xyz="0.0 0.0 0.06963"  rpy="0.0 0.0 0.0" />
   <geometry >
    <box  size="0.0335 0.0335 0.10575622865782347" />
   </geometry>
   <material  name="L4_Material" >
    <color  rgba="0.0 0.6627450980392157 0.3607843137254902 1.0" />
   </material>
  </visual>
  <collision  name="L4_Collision" >
   <origin  xyz="0.0 0.0 0.06963"  rpy="0.0 0.0 0.0" />
   <geometry >
    <box  size="0.0335 0.0335 0.10575622865782347" />
   </geometry>
  </collision>
  <inertial >
   <origin  xyz="0.0 0.0 0.06963"  rpy="0.0 0.0 0.0" />
   <mass  value="0.08587091882528611" />
   <inertia  iyy="8.806513476244757e-05"  iyz="0.0"  ixx="8.806513476244757e-05"  izz="1.6061439775279558e-05"  ixz="0.0"  ixy="0.0" />
  </inertial>
 </link>
 <joint  type="revolute"  name="Main_ground" >
  <parent  link="G" />
  <child  link="L6" />
  <origin  xyz="0.0 0.0 0.0"  rpy="3.141592653589793 0.17568468600617115 3.141592653589793" />
  <axis  xyz="0 1 0" />
  <limit  lower="-3.141592653589793"  upper="3.141592653589793"  effort="10.2"  velocity="23.99988291783386" />
  <dynamics  damping="0.05"  friction="0" />
 </joint>
 <joint  type="fixed"  name="Main_ground_G_WeldActuator" >
  <parent  link="G" />
  <child  link="Main_ground_GActuator" />
  <origin  xyz="0.0 0.036750000000000005 0.0"  rpy="-1.5707963267948966 0.17568468600617115 -3.141592653589793" />
 </joint>
 <link  name="Main_ground_GActuator" >
  <visual >
   <geometry >
    <cylinder  radius="0.048"  length="0.04" />
   </geometry>
   <material  name="Main_ground_GActuator_Material" >
    <color  rgba="0.1568627450980392 0.42745098039215684 0.8 0.9" />
   </material>
  </visual>
  <inertial >
   <inertia  iyy="0.0067466666666666664"  iyz="0.0"  ixx="0.0067466666666666664"  izz="0.01056"  ixz="0.0"  ixy="0.0" />
   <mass  value="0.44" />
  </inertial>
 </link>
 <link  name="Main_ground_GUnit" >
  <visual >
   <geometry >
    <cylinder  radius="0.01675"  length="0.0335" />
   </geometry>
   <material  name="Main_ground_GUnit_Material" >
    <color  rgba="0.1568627450980392 0.42745098039215684 0.8 0.9" />
   </material>
  </visual>
  <inertial >
   <inertia  iyy="0.0006979166666666668"  iyz="0.0"  ixx="0.0006979166666666668"  izz="0.0008375000000000001"  ixz="0.0"  ixy="0.0" />
   <mass  value="0.1" />
  </inertial>
 </link>
 <joint  type="fixed"  name="Main_ground_G_WeldUnit" >
  <parent  link="G" />
  <child  link="Main_ground_GUnit" />
  <origin  xyz="0.0 0.0 0.0"  rpy="-1.5707963267948966 0.17568468600617115 -3.141592653589793" />
 </joint>
 <joint  type="revolute"  name="Main_knee" >
  <parent  link="L6" />
  <child  link="L5" />
  <origin  xyz="3.822806484383419e-17 0.0 0.17164206943520577"  rpy="0.0 0.3048319761341911 0.0" />
  <axis  xyz="0 1 0" />
  <limit  lower="-3.141592653589793"  upper="3.141592653589793"  effort="600.0"  velocity="6.283185307179586" />
  <dynamics  damping="0.05"  friction="0" />
 </joint>
 <link  name="Main_knee_L6Unit" >
  <visual >
   <geometry >
    <cylinder  radius="0.016"  length="0.03" />
   </geometry>
   <material  name="Main_knee_L6Unit_Material" >
    <color  rgba="0.37254901960784315 0.5019607843137255 0.8352941176470589 0.9" />
   </material>
  </visual>
  <inertial >
   <inertia  iyy="0.00065"  iyz="0.0"  ixx="0.00065"  izz="0.0008"  ixz="0.0"  ixy="0.0" />
   <mass  value="0.1" />
  </inertial>
 </link>
 <joint  type="fixed"  name="Main_knee_L6_WeldUnit" >
  <parent  link="L6" />
  <child  link="Main_knee_L6Unit" />
  <origin  xyz="3.822806484383419e-17 0.0 0.17164206943520577"  rpy="1.5707963267948966 0.3048319761341911 -1.1102230246251565e-16" />
 </joint>
 <joint  type="fixed"  name="Main_ee" >
  <parent  link="L5" />
  <child  link="EE" />
  <origin  xyz="0.0 0.0 0.23293990641364998"  rpy="3.141592653589793 0.12914729012801995 3.141592653589793" />
 </joint>
 <link  name="Main_ee_L5Unit" >
  <visual >
   <geometry >
    <cylinder  radius="0.016"  length="0.03" />
   </geometry>
   <material  name="Main_ee_L5Unit_Material" >
    <color  rgba="0.5176470588235295 0.5843137254901961 0.8705882352941177 0.9" />
   </material>
  </visual>
  <inertial >
   <inertia  iyy="0.00065"  iyz="0.0"  ixx="0.00065"  izz="0.0008"  ixz="0.0"  ixy="0.0" />
   <mass  value="0.1" />
  </inertial>
 </link>
 <joint  type="fixed"  name="Main_ee_L5_WeldUnit" >
  <parent  link="L5" />
  <child  link="Main_ee_L5Unit" />
  <origin  xyz="0.0 0.0 0.23293990641364998"  rpy="-1.5707963267948966 0.12914729012802018 -3.141592653589793" />
 </joint>
 <joint  type="revolute"  name="Ground_connection" >
  <parent  link="G" />
  <child  link="L3" />
  <origin  xyz="-0.025 0.0 0.022"  rpy="3.141592653589793 -0.09416513073150834 3.141592653589793" />
  <axis  xyz="0 1 0" />
  <limit  lower="-3.141592653589793"  upper="3.141592653589793"  effort="10.2"  velocity="23.99988291783386" />
  <dynamics  damping="0.05"  friction="0" />
 </joint>
 <joint  type="fixed"  name="Ground_connection_G_WeldActuator" >
  <parent  link="G" />
  <child  link="Ground_connection_GActuator" />
  <origin  xyz="-0.025 0.036750000000000005 0.022"  rpy="-1.5707963267948966 -0.09416513073150812 -3.141592653589793" />
 </joint>
 <link  name="Ground_connection_GActuator" >
  <visual >
   <geometry >
    <cylinder  radius="0.048"  length="0.04" />
   </geometry>
   <material  name="Ground_connection_GActuator_Material" >
    <color  rgba="0.1568627450980392 0.42745098039215684 0.8 0.9" />
   </material>
  </visual>
  <inertial >
   <inertia  iyy="0.0067466666666666664"  iyz="0.0"  ixx="0.0067466666666666664"  izz="0.01056"  ixz="0.0"  ixy="0.0" />
   <mass  value="0.44" />
  </inertial>
 </link>
 <link  name="Ground_connection_GUnit" >
  <visual >
   <geometry >
    <cylinder  radius="0.01675"  length="0.0335" />
   </geometry>
   <material  name="Ground_connection_GUnit_Material" >
    <color  rgba="0.1568627450980392 0.42745098039215684 0.8 0.9" />
   </material>
  </visual>
  <inertial >
   <inertia  iyy="0.0006979166666666668"  iyz="0.0"  ixx="0.0006979166666666668"  izz="0.0008375000000000001"  ixz="0.0"  ixy="0.0" />
   <mass  value="0.1" />
  </inertial>
 </link>
 <joint  type="fixed"  name="Ground_connection_G_WeldUnit" >
  <parent  link="G" />
  <child  link="Ground_connection_GUnit" />
  <origin  xyz="-0.025 0.0 0.022"  rpy="-1.5707963267948966 -0.09416513073150812 -3.141592653589793" />
 </joint>
 <joint  type="revolute"  name="branch_1" >
  <parent  link="L3" />
  <child  link="L4" />
  <origin  xyz="6.245004513516506e-17 0.0 0.1808009955724802"  rpy="0.0 -0.4422649490070616 0.0" />
  <axis  xyz="0 1 0" />
  <limit  lower="-3.141592653589793"  upper="3.141592653589793"  effort="600.0"  velocity="6.283185307179586" />
  <dynamics  damping="0.05"  friction="0" />
 </joint>
 <link  name="branch_1_L3Unit" >
  <visual >
   <geometry >
    <cylinder  radius="0.016"  length="0.03" />
   </geometry>
   <material  name="branch_1_L3Unit_Material" >
    <color  rgba="0.01568627450980392 0.5058823529411764 0.29411764705882354 0.9" />
   </material>
  </visual>
  <inertial >
   <inertia  iyy="0.00065"  iyz="0.0"  ixx="0.00065"  izz="0.0008"  ixz="0.0"  ixy="0.0" />
   <mass  value="0.1" />
  </inertial>
 </link>
 <joint  type="fixed"  name="branch_1_L3_WeldUnit" >
  <parent  link="L3" />
  <child  link="branch_1_L3Unit" />
  <origin  xyz="6.245004513516506e-17 0.0 0.1808009955724802"  rpy="1.5707963267948966 -0.4422649490070618 -1.1102230246251565e-16" />
 </joint>
 <link  name="Main_connection_2_L5Pseudo" >
  <visual >
   <geometry >
    <sphere  radius="0.02392857202461788" />
   </geometry>
   <material  name="Main_connection_2_L5Pseudo_Material" >
    <color  rgba="0.5176470588235295 0.5843137254901961 0.8705882352941177 0.5" />
   </material>
  </visual>
  <inertial >
   <mass  value="0.05" />
   <inertia  iyy="1.145153118274651e-05"  iyz="0.0"  ixx="1.145153118274651e-05"  izz="1.145153118274651e-05"  ixz="0.0"  ixy="0.0" />
  </inertial>
 </link>
 <joint  type="revolute"  name="Main_connection_2_L5_revolute" >
  <parent  link="L5" />
  <child  link="Main_connection_2_L5Pseudo" />
  <origin  xyz="0.008851716443718696 0.0 0.1220605109607526"  rpy="3.141592653589793 0.12914729012801995 3.141592653589793" />
  <axis  xyz="0 1 0" />
  <limit  lower="-3.141592653589793"  upper="3.141592653589793"  effort="600.0"  velocity="6.283185307179586" />
  <dynamics  damping="0.05"  friction="0" />
 </joint>
 <joint  type="fixed"  name="Main_connection_2_L5_Weld" >
  <parent  link="L4" />
  <child  link="Main_connection_2_L4Pseudo" />
  <origin  xyz="1.3877787807814457e-17 0.0 0.13925622865782344"  rpy="3.141592653589793 -0.3480998182755537 3.141592653589793" />
 </joint>
 <link  name="Main_connection_2_L4Pseudo" >
  <visual >
   <geometry >
    <sphere  radius="0.02392857142857143" />
   </geometry>
   <material  name="Main_connection_2_L4Pseudo_Material" >
    <color  rgba="0.0 0.6627450980392157 0.3607843137254902 0.5" />
   </material>
  </visual>
  <inertial >
   <mass  value="0.05" />
   <inertia  iyy="1.1451530612244902e-05"  iyz="0.0"  ixx="1.1451530612244902e-05"  izz="1.1451530612244902e-05"  ixz="0.0"  ixy="0.0" />
  </inertial>
 </link>
</robot>
